<?xml version="1.0"?>
<robot xmlns:xacro="http://www.ros.org/wiki/xacro">

    <xacro:include filename="inertial_macros.xacro"/>

    <!-- links and joints go here -->

    <!-- The rest of the robot can be described from base_link, which is the centre point of the four driving wheels -->
    <link name="base_link">
    </link>

    <!-- chassis joint goes here. It connects chassis to base_link via fixed joint -->
    <joint name="chassis_joint" type="fixed">
        <parent link="base_link"/>
        <child link="chassis"/>
        <origin xyz="0 0 0"/>
    </joint>
    <!-- chassis description goes here. It describes the chassis of robocock which is a 54cm x 54cm x 150cm box -->
    <link name="chassis">
        <visual>
            <!-- by default, the origin is centred around the link origin, so offset it by half the height -->
            <!-- <origin xyz="0 0 0.75" rpy="0 0 0"/> -->
            <geometry>
                <!-- <box size="0.54 0.54 1.5"/> -->
                <mesh filename="package://robocock/meshes/frame_ultra_low_poly.stl"/>
                <!-- <mesh filename="model://frame_ultra_low_poly.stl"/> -->
            </geometry>
            <material name="white"/>
        </visual>
        <!-- physics model -->
        <collision>
            <origin xyz="0 0 0.75" rpy="0 0 0"/>
            <geometry>
                <box size="0.54 0.54 1.5"/>
            </geometry>
        </collision>
        <xacro:inertial_box mass="10" x="0.54" y="0.54" z="1.5">
            <origin xyz="0 0 0.75" rpy="0 0 0"/>
        </xacro:inertial_box>
    </link>
    <!-- gazebo specific description -->
    <gazebo reference="chassis">
        <material>Gazebo/White</material>
    </gazebo>

    <!-- FRONT LEFT WHEEL AKA wheel_1 -->
    <joint name="wheel_1_joint" type="continuous">
        <parent link="base_link"/>
        <child link="wheel_1"/>
        <origin xyz="0.1575 0.1575 0" rpy="-${pi/2} 0 -${pi/4}"/>
        <axis xyz="0 0 1"/>
    </joint>

    <link name="wheel_1">
        <visual>
            <geometry>      
                <cylinder length="0.038" radius="0.05" />
            </geometry>
            <material name="black"/>
        </visual>
        <collision>
            <geometry>      
                <cylinder length="0.038" radius="0.05" />
            </geometry>
        </collision>
        <xacro:inertial_cylinder mass="0.2" length="0.038" radius="0.05">
            <origin xyz="0 0 0" rpy="0 0 0"/>
        </xacro:inertial_cylinder>
    </link>

    <gazebo reference="wheel_1">
        <material>Gazebo/Black</material>
        <mu1 value="0.2"/>
        <mu2 value="1.5"/>
        <kp value="10000000.0" />
        <kd value="10000.0" />
        <fdir1 value="0 0 1"/>
        <maxContacts value= "1"/>
    </gazebo>

    <!-- FRONT RIGHT WHEEL AKA wheel_2 -->
    <joint name="wheel_2_joint" type="continuous">
        <parent link="base_link"/>
        <child link="wheel_2"/>
        <origin xyz="0.1575 -0.1575 0" rpy="${pi/2} 0 ${pi/4}"/>
        <axis xyz="0 0 -1"/>
    </joint>

    <link name="wheel_2">
        <visual>
            <geometry>      
                <cylinder length="0.038" radius="0.05" />
            </geometry>
            <material name="black"/>
        </visual>
        <collision>
            <geometry>      
                <cylinder length="0.038" radius="0.05" />
            </geometry>
        </collision>
        <xacro:inertial_cylinder mass="0.2" length="0.038" radius="0.05">
            <origin xyz="0 0 0" rpy="0 0 0"/>
        </xacro:inertial_cylinder>
    </link>

    <gazebo reference="wheel_2">
        <material>Gazebo/Black</material>
        <mu1 value="0.2"/>
        <mu2 value="1.5"/>
        <kp value="10000000.0" />
        <kd value="10000.0" />
        <fdir1 value="0 0 1"/>
        <maxContacts value= "1"/>
    </gazebo>

    <!-- REAR LEFT WHEEL AKA wheel_3 -->
    <joint name="wheel_3_joint" type="continuous">
        <parent link="base_link"/>
        <child link="wheel_3"/>
        <origin xyz="-0.1575 0.1575 0" rpy="-${pi/2} 0 ${pi/4}"/>
        <axis xyz="0 0 1"/>
    </joint>

    <link name="wheel_3">
        <visual>
            <geometry>      
                <cylinder length="0.038" radius="0.05" />
            </geometry>
            <material name="black"/>
        </visual>
        <collision>
            <geometry>      
                <cylinder length="0.038" radius="0.05" />
            </geometry>
        </collision>
        <xacro:inertial_cylinder mass="0.2" length="0.038" radius="0.05">
            <origin xyz="0 0 0" rpy="0 0 0"/>
        </xacro:inertial_cylinder>
    </link>

    <gazebo reference="wheel_3">
        <material>Gazebo/Black</material>
        <mu1 value="0.2"/>
        <mu2 value="1.5"/>
        <kp value="10000000.0" />
        <kd value="10000.0" />
        <fdir1 value="0 0 1"/>
        <maxContacts value= "1"/>
    </gazebo>

    <!-- REAR RIGHT WHEEL AKA wheel_4 -->
    <joint name="wheel_4_joint" type="continuous">
        <parent link="base_link"/>
        <child link="wheel_4"/>
        <origin xyz="-0.1575 -0.1575 0" rpy="${pi/2} 0 -${pi/4}"/>
        <axis xyz="0 0 -1"/>
    </joint>

    <link name="wheel_4">
        <visual>
            <geometry>      
                <cylinder length="0.038" radius="0.05" />
            </geometry>
            <material name="black"/>
        </visual>
        <collision>
            <geometry>      
                <cylinder length="0.038" radius="0.05" />
            </geometry>
        </collision>
        <xacro:inertial_cylinder mass="0.2" length="0.038" radius="0.05">
            <origin xyz="0 0 0" rpy="0 0 0"/>
        </xacro:inertial_cylinder>
    </link>

    <gazebo reference="wheel_4">
        <material>Gazebo/Black</material>
        <mu1 value="0.2"/>
        <mu2 value="1.5"/>
        <kp value="10000000.0" />
        <kd value="10000.0" />
        <fdir1 value="0 0 1"/>
        <maxContacts value= "1"/>
    </gazebo>

    <!-- Make Gazebo publish joint states -->
    <gazebo>
        <plugin name="gazebo_row_joint_state_publisher"
            filename="libgazebo_ros_joint_state_publisher.so">
            <update_rate>30</update_rate>
            <joint_name>wheel_1_joint</joint_name>
            <joint_name>wheel_2_joint</joint_name>
            <joint_name>wheel_3_joint</joint_name>
            <joint_name>wheel_4_joint</joint_name>
            <!-- <joint_name>base_link_joint</joint_name>     -->
        </plugin>
    </gazebo>

</robot>